[2022-08-24 09:45:00,677] {taskinstance.py:1179} INFO - Dependencies all met for <TaskInstance: taxi_rides_data.s3_create_object manual__2022-08-24T09:44:56.043687+00:00 [queued]>
[2022-08-24 09:45:00,682] {taskinstance.py:1179} INFO - Dependencies all met for <TaskInstance: taxi_rides_data.s3_create_object manual__2022-08-24T09:44:56.043687+00:00 [queued]>
[2022-08-24 09:45:00,682] {taskinstance.py:1376} INFO - 
--------------------------------------------------------------------------------
[2022-08-24 09:45:00,682] {taskinstance.py:1377} INFO - Starting attempt 1 of 1
[2022-08-24 09:45:00,682] {taskinstance.py:1378} INFO - 
--------------------------------------------------------------------------------
[2022-08-24 09:45:00,691] {taskinstance.py:1397} INFO - Executing <Task(S3CreateObjectOperator): s3_create_object> on 2022-08-24 09:44:56.043687+00:00
[2022-08-24 09:45:00,695] {standard_task_runner.py:52} INFO - Started process 4548 to run task
[2022-08-24 09:45:00,697] {standard_task_runner.py:79} INFO - Running: ['***', 'tasks', 'run', 'taxi_rides_data', 's3_create_object', 'manual__2022-08-24T09:44:56.043687+00:00', '--job-id', '11', '--raw', '--subdir', 'DAGS_FOLDER/taxi_rides_dag.py', '--cfg-path', '/tmp/tmp24pbvf1f', '--error-file', '/tmp/tmp1woe4wu6']
[2022-08-24 09:45:00,697] {standard_task_runner.py:80} INFO - Job 11: Subtask s3_create_object
[2022-08-24 09:45:00,736] {task_command.py:371} INFO - Running <TaskInstance: taxi_rides_data.s3_create_object manual__2022-08-24T09:44:56.043687+00:00 [running]> on host ddc8002727e0
[2022-08-24 09:45:00,915] {taskinstance.py:1591} INFO - Exporting the following env vars:
AIRFLOW_CTX_DAG_OWNER=***
AIRFLOW_CTX_DAG_ID=taxi_rides_data
AIRFLOW_CTX_TASK_ID=s3_create_object
AIRFLOW_CTX_EXECUTION_DATE=2022-08-24T09:44:56.043687+00:00
AIRFLOW_CTX_TRY_NUMBER=1
AIRFLOW_CTX_DAG_RUN_ID=manual__2022-08-24T09:44:56.043687+00:00
[2022-08-24 09:45:00,915] {taskinstance.py:1909} ERROR - Task failed with exception
Traceback (most recent call last):
  File "/home/airflow/.local/lib/python3.7/site-packages/airflow/providers/amazon/aws/operators/s3.py", line 410, in execute
    s3_hook.load_bytes(self.data, s3_key, s3_bucket, self.replace, self.encrypt, self.acl_policy)
  File "/home/airflow/.local/lib/python3.7/site-packages/airflow/providers/amazon/aws/hooks/s3.py", line 63, in wrapper
    return func(*bound_args.args, **bound_args.kwargs)
  File "/home/airflow/.local/lib/python3.7/site-packages/airflow/providers/amazon/aws/hooks/s3.py", line 91, in wrapper
    return func(*bound_args.args, **bound_args.kwargs)
  File "/home/airflow/.local/lib/python3.7/site-packages/airflow/providers/amazon/aws/hooks/s3.py", line 690, in load_bytes
    file_obj = io.BytesIO(bytes_data)
TypeError: a bytes-like object is required, not 'ZipExtFile'
[2022-08-24 09:45:00,920] {taskinstance.py:1420} INFO - Marking task as FAILED. dag_id=taxi_rides_data, task_id=s3_create_object, execution_date=20220824T094456, start_date=20220824T094500, end_date=20220824T094500
[2022-08-24 09:45:00,928] {standard_task_runner.py:97} ERROR - Failed to execute job 11 for task s3_create_object (a bytes-like object is required, not 'ZipExtFile'; 4548)
[2022-08-24 09:45:00,949] {local_task_job.py:156} INFO - Task exited with return code 1
[2022-08-24 09:45:00,969] {local_task_job.py:273} INFO - 0 downstream tasks scheduled from follow-on schedule check
