[2022-08-25 11:19:09,309] {taskinstance.py:1179} INFO - Dependencies all met for <TaskInstance: taxi_rides_data.transfer_s3_to_redshift manual__2022-08-25T11:19:03.318024+00:00 [queued]>
[2022-08-25 11:19:09,319] {taskinstance.py:1179} INFO - Dependencies all met for <TaskInstance: taxi_rides_data.transfer_s3_to_redshift manual__2022-08-25T11:19:03.318024+00:00 [queued]>
[2022-08-25 11:19:09,320] {taskinstance.py:1376} INFO - 
--------------------------------------------------------------------------------
[2022-08-25 11:19:09,320] {taskinstance.py:1377} INFO - Starting attempt 1 of 1
[2022-08-25 11:19:09,320] {taskinstance.py:1378} INFO - 
--------------------------------------------------------------------------------
[2022-08-25 11:19:09,336] {taskinstance.py:1397} INFO - Executing <Task(S3ToRedshiftOperator): transfer_s3_to_redshift> on 2022-08-25 11:19:03.318024+00:00
[2022-08-25 11:19:09,341] {standard_task_runner.py:52} INFO - Started process 7329 to run task
[2022-08-25 11:19:09,344] {standard_task_runner.py:79} INFO - Running: ['***', 'tasks', 'run', 'taxi_rides_data', 'transfer_s3_to_redshift', 'manual__2022-08-25T11:19:03.318024+00:00', '--job-id', '68', '--raw', '--subdir', 'DAGS_FOLDER/taxi_rides_dag.py', '--cfg-path', '/tmp/tmpvw91f_0v', '--error-file', '/tmp/tmpk_je0tn_']
[2022-08-25 11:19:09,345] {standard_task_runner.py:80} INFO - Job 68: Subtask transfer_s3_to_redshift
[2022-08-25 11:19:09,409] {task_command.py:371} INFO - Running <TaskInstance: taxi_rides_data.transfer_s3_to_redshift manual__2022-08-25T11:19:03.318024+00:00 [running]> on host ddc8002727e0
[2022-08-25 11:19:09,494] {taskinstance.py:1591} INFO - Exporting the following env vars:
AIRFLOW_CTX_DAG_OWNER=***
AIRFLOW_CTX_DAG_ID=taxi_rides_data
AIRFLOW_CTX_TASK_ID=transfer_s3_to_redshift
AIRFLOW_CTX_EXECUTION_DATE=2022-08-25T11:19:03.318024+00:00
AIRFLOW_CTX_TRY_NUMBER=1
AIRFLOW_CTX_DAG_RUN_ID=manual__2022-08-25T11:19:03.318024+00:00
[2022-08-25 11:19:09,507] {base.py:68} INFO - Using connection ID 'aws_credentials' for task execution.
[2022-08-25 11:19:09,513] {base.py:68} INFO - Using connection ID 'aws_credentials' for task execution.
[2022-08-25 11:19:09,513] {base_aws.py:206} INFO - Credentials retrieved from login
[2022-08-25 11:19:09,528] {s3_to_redshift.py:167} INFO - Executing COPY command...
[2022-08-25 11:19:09,534] {base.py:68} INFO - Using connection ID 'redshift_default' for task execution.
[2022-08-25 11:19:10,887] {dbapi.py:231} INFO - Running statement: 
                    COPY PUBLIC.raw__taxigov_corridas 
                    FROM 's3://brazilian-politicians-taxi-rides/taxigov_corridas.csv'
                    credentials
                    'aws_access_key_id=AKIAR2G6RXW7IQF76DLJ;aws_secret_access_key=***'
                    csv;
        , parameters: None
[2022-08-25 11:19:21,392] {taskinstance.py:1909} ERROR - Task failed with exception
Traceback (most recent call last):
  File "/home/airflow/.local/lib/python3.7/site-packages/airflow/providers/amazon/aws/transfers/s3_to_redshift.py", line 168, in execute
    redshift_hook.run(sql, autocommit=self.autocommit)
  File "/home/airflow/.local/lib/python3.7/site-packages/airflow/hooks/dbapi.py", line 211, in run
    self._run_command(cur, sql_statement, parameters)
  File "/home/airflow/.local/lib/python3.7/site-packages/airflow/hooks/dbapi.py", line 235, in _run_command
    cur.execute(sql_statement)
  File "/home/airflow/.local/lib/python3.7/site-packages/redshift_connector/cursor.py", line 240, in execute
    self._c.execute(self, operation, args)
  File "/home/airflow/.local/lib/python3.7/site-packages/redshift_connector/core.py", line 1783, in execute
    self.handle_messages(cursor)
  File "/home/airflow/.local/lib/python3.7/site-packages/redshift_connector/core.py", line 1969, in handle_messages
    raise self.error
redshift_connector.error.ProgrammingError: {'S': 'ERROR', 'C': 'XX000', 'M': "Load into table 'raw__taxigov_corridas' failed.  Check 'stl_load_errors' system table for details.", 'F': '../src/pg/src/backend/commands/commands_copy.c', 'L': '693', 'R': 'CheckMaxRowError'}
[2022-08-25 11:19:21,403] {taskinstance.py:1420} INFO - Marking task as FAILED. dag_id=taxi_rides_data, task_id=transfer_s3_to_redshift, execution_date=20220825T111903, start_date=20220825T111909, end_date=20220825T111921
[2022-08-25 11:19:21,416] {standard_task_runner.py:97} ERROR - Failed to execute job 68 for task transfer_s3_to_redshift ({'S': 'ERROR', 'C': 'XX000', 'M': "Load into table 'raw__taxigov_corridas' failed.  Check 'stl_load_errors' system table for details.", 'F': '../src/pg/src/backend/commands/commands_copy.c', 'L': '693', 'R': 'CheckMaxRowError'}; 7329)
[2022-08-25 11:19:21,434] {local_task_job.py:156} INFO - Task exited with return code 1
[2022-08-25 11:19:21,460] {local_task_job.py:273} INFO - 0 downstream tasks scheduled from follow-on schedule check
