[2022-08-28 23:13:20,686] {taskinstance.py:1179} INFO - Dependencies all met for <TaskInstance: create_and_populate_taxigov_datawarehouse.check_taxigov_data manual__2022-08-28T23:13:19.866701+00:00 [queued]>
[2022-08-28 23:13:20,694] {taskinstance.py:1179} INFO - Dependencies all met for <TaskInstance: create_and_populate_taxigov_datawarehouse.check_taxigov_data manual__2022-08-28T23:13:19.866701+00:00 [queued]>
[2022-08-28 23:13:20,694] {taskinstance.py:1376} INFO - 
--------------------------------------------------------------------------------
[2022-08-28 23:13:20,694] {taskinstance.py:1377} INFO - Starting attempt 1 of 1
[2022-08-28 23:13:20,694] {taskinstance.py:1378} INFO - 
--------------------------------------------------------------------------------
[2022-08-28 23:13:20,704] {taskinstance.py:1397} INFO - Executing <Task(PythonOperator): check_taxigov_data> on 2022-08-28 23:13:19.866701+00:00
[2022-08-28 23:13:20,707] {standard_task_runner.py:52} INFO - Started process 2182 to run task
[2022-08-28 23:13:20,710] {standard_task_runner.py:79} INFO - Running: ['***', 'tasks', 'run', 'create_and_populate_taxigov_datawarehouse', 'check_taxigov_data', 'manual__2022-08-28T23:13:19.866701+00:00', '--job-id', '91', '--raw', '--subdir', 'DAGS_FOLDER/create_and_populate_taxigov_datawarehouse_dag.py', '--cfg-path', '/tmp/tmpb_g718dv', '--error-file', '/tmp/tmpjo0t88bs']
[2022-08-28 23:13:20,710] {standard_task_runner.py:80} INFO - Job 91: Subtask check_taxigov_data
[2022-08-28 23:13:20,759] {task_command.py:371} INFO - Running <TaskInstance: create_and_populate_taxigov_datawarehouse.check_taxigov_data manual__2022-08-28T23:13:19.866701+00:00 [running]> on host ddc8002727e0
[2022-08-28 23:13:20,818] {taskinstance.py:1591} INFO - Exporting the following env vars:
AIRFLOW_CTX_DAG_OWNER=***
AIRFLOW_CTX_DAG_ID=create_and_populate_taxigov_datawarehouse
AIRFLOW_CTX_TASK_ID=check_taxigov_data
AIRFLOW_CTX_EXECUTION_DATE=2022-08-28T23:13:19.866701+00:00
AIRFLOW_CTX_TRY_NUMBER=1
AIRFLOW_CTX_DAG_RUN_ID=manual__2022-08-28T23:13:19.866701+00:00
[2022-08-28 23:13:20,828] {base.py:68} INFO - Using connection ID 'redshift_default' for task execution.
[2022-08-28 23:13:22,963] {taskinstance.py:1909} ERROR - Task failed with exception
Traceback (most recent call last):
  File "/home/airflow/.local/lib/python3.7/site-packages/airflow/operators/python.py", line 171, in execute
    return_value = self.execute_callable()
  File "/home/airflow/.local/lib/python3.7/site-packages/airflow/operators/python.py", line 189, in execute_callable
    return self.python_callable(*self.op_args, **self.op_kwargs)
  File "/opt/airflow/dags/create_and_populate_taxigov_datawarehouse_dag.py", line 14, in check_dependencies
    records = redshift_hook.get_records(f"SELECT COUNT(*) FROM {table}")
  File "/home/airflow/.local/lib/python3.7/site-packages/airflow/hooks/dbapi.py", line 162, in get_records
    cur.execute(sql)
psycopg2.errors.UndefinedTable: relation "raw__taxigov_corridas" does not exist

[2022-08-28 23:13:22,981] {taskinstance.py:1420} INFO - Marking task as FAILED. dag_id=create_and_populate_taxigov_datawarehouse, task_id=check_taxigov_data, execution_date=20220828T231319, start_date=20220828T231320, end_date=20220828T231322
[2022-08-28 23:13:22,996] {standard_task_runner.py:97} ERROR - Failed to execute job 91 for task check_taxigov_data (relation "raw__taxigov_corridas" does not exist
; 2182)
[2022-08-28 23:13:23,009] {local_task_job.py:156} INFO - Task exited with return code 1
[2022-08-28 23:13:23,093] {local_task_job.py:273} INFO - 0 downstream tasks scheduled from follow-on schedule check
