[2022-08-24 09:52:41,471] {taskinstance.py:1179} INFO - Dependencies all met for <TaskInstance: taxi_rides_data.s3_create_object manual__2022-08-24T09:52:32.754350+00:00 [queued]>
[2022-08-24 09:52:41,481] {taskinstance.py:1179} INFO - Dependencies all met for <TaskInstance: taxi_rides_data.s3_create_object manual__2022-08-24T09:52:32.754350+00:00 [queued]>
[2022-08-24 09:52:41,481] {taskinstance.py:1376} INFO - 
--------------------------------------------------------------------------------
[2022-08-24 09:52:41,481] {taskinstance.py:1377} INFO - Starting attempt 1 of 1
[2022-08-24 09:52:41,481] {taskinstance.py:1378} INFO - 
--------------------------------------------------------------------------------
[2022-08-24 09:52:41,498] {taskinstance.py:1397} INFO - Executing <Task(S3CreateObjectOperator): s3_create_object> on 2022-08-24 09:52:32.754350+00:00
[2022-08-24 09:52:41,506] {standard_task_runner.py:52} INFO - Started process 4910 to run task
[2022-08-24 09:52:41,508] {standard_task_runner.py:79} INFO - Running: ['***', 'tasks', 'run', 'taxi_rides_data', 's3_create_object', 'manual__2022-08-24T09:52:32.754350+00:00', '--job-id', '12', '--raw', '--subdir', 'DAGS_FOLDER/taxi_rides_dag.py', '--cfg-path', '/tmp/tmpmg65sxyq', '--error-file', '/tmp/tmpgeuo31pr']
[2022-08-24 09:52:41,508] {standard_task_runner.py:80} INFO - Job 12: Subtask s3_create_object
[2022-08-24 09:52:41,558] {task_command.py:371} INFO - Running <TaskInstance: taxi_rides_data.s3_create_object manual__2022-08-24T09:52:32.754350+00:00 [running]> on host ddc8002727e0
[2022-08-24 09:52:48,414] {taskinstance.py:1591} INFO - Exporting the following env vars:
AIRFLOW_CTX_DAG_OWNER=***
AIRFLOW_CTX_DAG_ID=taxi_rides_data
AIRFLOW_CTX_TASK_ID=s3_create_object
AIRFLOW_CTX_EXECUTION_DATE=2022-08-24T09:52:32.754350+00:00
AIRFLOW_CTX_TRY_NUMBER=1
AIRFLOW_CTX_DAG_RUN_ID=manual__2022-08-24T09:52:32.754350+00:00
[2022-08-24 09:52:49,510] {base_aws.py:447} WARNING - Unable to use Airflow Connection for credentials.
[2022-08-24 09:52:51,732] {taskinstance.py:1909} ERROR - Task failed with exception
Traceback (most recent call last):
  File "/home/airflow/.local/lib/python3.7/site-packages/airflow/providers/amazon/aws/operators/s3.py", line 410, in execute
    s3_hook.load_bytes(self.data, s3_key, s3_bucket, self.replace, self.encrypt, self.acl_policy)
  File "/home/airflow/.local/lib/python3.7/site-packages/airflow/providers/amazon/aws/hooks/s3.py", line 63, in wrapper
    return func(*bound_args.args, **bound_args.kwargs)
  File "/home/airflow/.local/lib/python3.7/site-packages/airflow/providers/amazon/aws/hooks/s3.py", line 91, in wrapper
    return func(*bound_args.args, **bound_args.kwargs)
  File "/home/airflow/.local/lib/python3.7/site-packages/airflow/providers/amazon/aws/hooks/s3.py", line 691, in load_bytes
    self._upload_file_obj(file_obj, key, bucket_name, replace, encrypt, acl_policy)
  File "/home/airflow/.local/lib/python3.7/site-packages/airflow/providers/amazon/aws/hooks/s3.py", line 744, in _upload_file_obj
    Config=self.transfer_config,
  File "/home/airflow/.local/lib/python3.7/site-packages/boto3/s3/inject.py", line 636, in upload_fileobj
    return future.result()
  File "/home/airflow/.local/lib/python3.7/site-packages/s3transfer/futures.py", line 103, in result
    return self._coordinator.result()
  File "/home/airflow/.local/lib/python3.7/site-packages/s3transfer/futures.py", line 266, in result
    raise self._exception
  File "/home/airflow/.local/lib/python3.7/site-packages/s3transfer/tasks.py", line 139, in __call__
    return self._execute_main(kwargs)
  File "/home/airflow/.local/lib/python3.7/site-packages/s3transfer/tasks.py", line 162, in _execute_main
    return_value = self._main(**kwargs)
  File "/home/airflow/.local/lib/python3.7/site-packages/s3transfer/tasks.py", line 349, in _main
    Bucket=bucket, Key=key, **extra_args
  File "/home/airflow/.local/lib/python3.7/site-packages/botocore/client.py", line 508, in _api_call
    return self._make_api_call(operation_name, kwargs)
  File "/home/airflow/.local/lib/python3.7/site-packages/botocore/client.py", line 899, in _make_api_call
    operation_model, request_dict, request_context
  File "/home/airflow/.local/lib/python3.7/site-packages/botocore/client.py", line 921, in _make_request
    return self._endpoint.make_request(operation_model, request_dict)
  File "/home/airflow/.local/lib/python3.7/site-packages/botocore/endpoint.py", line 119, in make_request
    return self._send_request(request_dict, operation_model)
  File "/home/airflow/.local/lib/python3.7/site-packages/botocore/endpoint.py", line 198, in _send_request
    request = self.create_request(request_dict, operation_model)
  File "/home/airflow/.local/lib/python3.7/site-packages/botocore/endpoint.py", line 137, in create_request
    operation_name=operation_model.name,
  File "/home/airflow/.local/lib/python3.7/site-packages/botocore/hooks.py", line 412, in emit
    return self._emitter.emit(aliased_event_name, **kwargs)
  File "/home/airflow/.local/lib/python3.7/site-packages/botocore/hooks.py", line 256, in emit
    return self._emit(event_name, kwargs)
  File "/home/airflow/.local/lib/python3.7/site-packages/botocore/hooks.py", line 239, in _emit
    response = handler(**kwargs)
  File "/home/airflow/.local/lib/python3.7/site-packages/botocore/signers.py", line 103, in handler
    return self.sign(operation_name, request)
  File "/home/airflow/.local/lib/python3.7/site-packages/botocore/signers.py", line 187, in sign
    auth.add_auth(request)
  File "/home/airflow/.local/lib/python3.7/site-packages/botocore/auth.py", line 407, in add_auth
    raise NoCredentialsError()
botocore.exceptions.NoCredentialsError: Unable to locate credentials
[2022-08-24 09:52:51,743] {taskinstance.py:1420} INFO - Marking task as FAILED. dag_id=taxi_rides_data, task_id=s3_create_object, execution_date=20220824T095232, start_date=20220824T095241, end_date=20220824T095251
[2022-08-24 09:52:51,753] {standard_task_runner.py:97} ERROR - Failed to execute job 12 for task s3_create_object (Unable to locate credentials; 4910)
[2022-08-24 09:52:51,791] {local_task_job.py:156} INFO - Task exited with return code 1
[2022-08-24 09:52:51,815] {local_task_job.py:273} INFO - 0 downstream tasks scheduled from follow-on schedule check
