[2022-08-27 15:25:54,499] {taskinstance.py:1179} INFO - Dependencies all met for <TaskInstance: taxi_rides_data.create_object scheduled__2022-08-26T10:32:38.642192+00:00 [queued]>
[2022-08-27 15:25:54,505] {taskinstance.py:1179} INFO - Dependencies all met for <TaskInstance: taxi_rides_data.create_object scheduled__2022-08-26T10:32:38.642192+00:00 [queued]>
[2022-08-27 15:25:54,505] {taskinstance.py:1376} INFO - 
--------------------------------------------------------------------------------
[2022-08-27 15:25:54,505] {taskinstance.py:1377} INFO - Starting attempt 1 of 1
[2022-08-27 15:25:54,505] {taskinstance.py:1378} INFO - 
--------------------------------------------------------------------------------
[2022-08-27 15:25:54,514] {taskinstance.py:1397} INFO - Executing <Task(S3CreateObjectOperator): create_object> on 2022-08-26 10:32:38.642192+00:00
[2022-08-27 15:25:54,518] {standard_task_runner.py:52} INFO - Started process 69 to run task
[2022-08-27 15:25:54,520] {standard_task_runner.py:79} INFO - Running: ['***', 'tasks', 'run', 'taxi_rides_data', 'create_object', 'scheduled__2022-08-26T10:32:38.642192+00:00', '--job-id', '81', '--raw', '--subdir', 'DAGS_FOLDER/taxi_rides_dag.py', '--cfg-path', '/tmp/tmpqcnpahxt', '--error-file', '/tmp/tmp0w14hwn0']
[2022-08-27 15:25:54,520] {standard_task_runner.py:80} INFO - Job 81: Subtask create_object
[2022-08-27 15:25:54,559] {task_command.py:371} INFO - Running <TaskInstance: taxi_rides_data.create_object scheduled__2022-08-26T10:32:38.642192+00:00 [running]> on host ddc8002727e0
[2022-08-27 15:26:00,361] {taskinstance.py:1591} INFO - Exporting the following env vars:
AIRFLOW_CTX_DAG_OWNER=***
AIRFLOW_CTX_DAG_ID=taxi_rides_data
AIRFLOW_CTX_TASK_ID=create_object
AIRFLOW_CTX_EXECUTION_DATE=2022-08-26T10:32:38.642192+00:00
AIRFLOW_CTX_TRY_NUMBER=1
AIRFLOW_CTX_DAG_RUN_ID=scheduled__2022-08-26T10:32:38.642192+00:00
[2022-08-27 15:26:00,368] {base.py:68} INFO - Using connection ID 'aws_credentials' for task execution.
[2022-08-27 15:26:00,368] {base_aws.py:206} INFO - Credentials retrieved from login
[2022-08-27 18:26:02,715] {taskinstance.py:1909} ERROR - Task failed with exception
Traceback (most recent call last):
  File "/home/airflow/.local/lib/python3.7/site-packages/airflow/providers/amazon/aws/operators/s3.py", line 410, in execute
    s3_hook.load_bytes(self.data, s3_key, s3_bucket, self.replace, self.encrypt, self.acl_policy)
  File "/home/airflow/.local/lib/python3.7/site-packages/airflow/providers/amazon/aws/hooks/s3.py", line 63, in wrapper
    return func(*bound_args.args, **bound_args.kwargs)
  File "/home/airflow/.local/lib/python3.7/site-packages/airflow/providers/amazon/aws/hooks/s3.py", line 91, in wrapper
    return func(*bound_args.args, **bound_args.kwargs)
  File "/home/airflow/.local/lib/python3.7/site-packages/airflow/providers/amazon/aws/hooks/s3.py", line 691, in load_bytes
    self._upload_file_obj(file_obj, key, bucket_name, replace, encrypt, acl_policy)
  File "/home/airflow/.local/lib/python3.7/site-packages/airflow/providers/amazon/aws/hooks/s3.py", line 744, in _upload_file_obj
    Config=self.transfer_config,
  File "/home/airflow/.local/lib/python3.7/site-packages/boto3/s3/inject.py", line 636, in upload_fileobj
    return future.result()
  File "/home/airflow/.local/lib/python3.7/site-packages/s3transfer/futures.py", line 103, in result
    return self._coordinator.result()
  File "/home/airflow/.local/lib/python3.7/site-packages/s3transfer/futures.py", line 266, in result
    raise self._exception
  File "/home/airflow/.local/lib/python3.7/site-packages/s3transfer/tasks.py", line 139, in __call__
    return self._execute_main(kwargs)
  File "/home/airflow/.local/lib/python3.7/site-packages/s3transfer/tasks.py", line 162, in _execute_main
    return_value = self._main(**kwargs)
  File "/home/airflow/.local/lib/python3.7/site-packages/s3transfer/tasks.py", line 349, in _main
    Bucket=bucket, Key=key, **extra_args
  File "/home/airflow/.local/lib/python3.7/site-packages/botocore/client.py", line 508, in _api_call
    return self._make_api_call(operation_name, kwargs)
  File "/home/airflow/.local/lib/python3.7/site-packages/botocore/client.py", line 915, in _make_api_call
    raise error_class(parsed_response, operation_name)
botocore.exceptions.ClientError: An error occurred (RequestTimeTooSkewed) when calling the CreateMultipartUpload operation: The difference between the request time and the current time is too large.
[2022-08-27 18:26:02,728] {taskinstance.py:1420} INFO - Marking task as FAILED. dag_id=taxi_rides_data, task_id=create_object, execution_date=20220826T103238, start_date=20220827T152554, end_date=20220827T182602
[2022-08-27 18:26:02,740] {standard_task_runner.py:97} ERROR - Failed to execute job 81 for task create_object (An error occurred (RequestTimeTooSkewed) when calling the CreateMultipartUpload operation: The difference between the request time and the current time is too large.; 69)
[2022-08-27 18:26:02,794] {local_task_job.py:156} INFO - Task exited with return code 1
[2022-08-27 18:26:02,820] {local_task_job.py:273} INFO - 0 downstream tasks scheduled from follow-on schedule check
